Workbook

Sheet PC Comp_R_1
C1: Final Grid
A2: Geo segment New | B2: Geo segment Old | C2: Comp - Petrol - NCB / NON NCB | D2: Comp - Diesel / Others - Non NCB | E2: Comp - Diesel / Others - NCB | F2: SOD - NON NCB | G2: SOD - NCB
A3: ANDHRA PRADESH - 1 KV | B3: ANDHRA PRADESH - KRISHNA(VIJAYWADA) | C3: 0.28 | D3: 0.21 | E3: 0.25 | F3: 0.185 | G3: 0.205
A4: ANDHRA PRADESH - 2 V | B4: ANDHRA PRADESH - VISAKHAPATNAM | C4: 0.27 | D4: 0.235 | E4: 0.235 | F4: 0.185 | G4: 0.19
A5: ANDHRA PRADESH - 3 R | B5: ANDHRA PRADESH - REST | C5: 0.27 | D5: 0.21 | E5: 0.25 | F5: 0.185 | G5: 0.19
A6: ARUNACHAL PRADESH | B6: ARUNACHAL PRADESH | C6: 0.215 | D6: 0.215 | E6: 0.215 | F6: 0.185 | G6: 0.19
A7: ASSAM - 1 GK | B7: ASSAM - KAMRUP (GUWAHATI) | C7: 0.215 | D7: 0.19 | E7: 0.19 | F7: 0.185 | G7: 0.19
A8: ASSAM - 2 U | B8: ASSAM - UPPER | C8: 0.215 | D8: 0.19 | E8: 0.19 | F8: 0.185 | G8: 0.19
A9: ASSAM - 3 R | B9: ASSAM - LOWER | C9: 0.215 | D9: 0.19 | E9: 0.19 | F9: 0.185 | G9: 0.19
A10: BIHAR | B10: BIHAR | C10: 0.28 | D10: 0.21 | E10: 0.26 | F10: 0.185 | G10: 0.19
A11: CHANDIGARH(TRICITY) | B11: CHANDIGARH(TRICITY) | C11: 0.295 | D11: 0.25 | E11: 0.245 | F11: 0.185 | G11: 0.25
A12: CHATTISGARH - 1 RA | B12: CHATTISGARH - RAIPUR | C12: 0 | D12: 0 | E12: 0 | F12: 0 | G12: 0
A13: CHATTISGARH - 2 R | B13: CHATTISGARH - REST | C13: 0 | D13: 0 | E13: 0 | F13: 0 | G13: 0
A14: DELHI - NCR | B14: DELHI - NCR | C14: 0.295 | D14: 0.26 | E14: 0.3 | F14: 0.185 | G14: 0.25
... A75: WEST BENGAL - REST | B75: WEST BENGAL - REST | C75: 0.28 | D75: 0.21 | E75: 0.26 | F75: 0.185 | G75: 0.205

Sheet Sheet1
A1: Geo segment Old | B1: Geo segment New
A2: ANDHRA PRADESH - KRISHNA(VIJAYWADA) | B2: ANDHRA PRADESH - 1 KV
A3: ANDHRA PRADESH - VISAKHAPATNAM | B3: ANDHRA PRADESH - 2 V
A4: ANDHRA PRADESH - REST | B4: ANDHRA PRADESH - 3 R
A5: ARUNACHAL PRADESH | B5: ARUNACHAL PRADESH
A6: ASSAM - KAMRUP (GUWAHATI) | B6: ASSAM - 1 GK
A7: ASSAM - UPPER | B7: ASSAM - 2 U
A8: ASSAM - LOWER | B8: ASSAM - 3 R
A9: BIHAR | B9: BIHAR
A10: CHANDIGARH(TRICITY) | B10: CHANDIGARH(TRICITY)
A11: CHATTISGARH - RAIPUR | B11: CHATTISGARH - 1 RA
A12: CHATTISGARH - REST | B12: CHATTISGARH - 2 R
... A73: WEST BENGAL - REST | B73: WEST BENGAL - 5 R

Sheet PC Comp_R
B1: March 2025 PAYOUT - PC COMP
B2: Geo Locations | C2: Payout on | D2: Comp - Petrol - NCB / NON NCB | E2: Comp - Diesel / Others - Non NCB | F2: Comp - Diesel / Others - NCB | G2: SOD - NON NCB | H2: SOD - NCB
A3: ANDHRA PRADESH - 1 KV | B3: ANDHRA PRADESH - KRISHNA(VIJAYWADA) | C3: OD Premium | D3: 0.28 | E3: 0.21 | F3: 0.25 | G3: 0.185 | H3: 0.205
A4: ANDHRA PRADESH - 3 R | B4: ANDHRA PRADESH - REST | C4: OD Premium | D4: 0.27 | E4: 0.21 | F4: 0.25 | G4: 0.185 | H4: 0.19
A5: ANDHRA PRADESH - 2 V | B5: ANDHRA PRADESH - VISAKHAPATNAM | C5: OD Premium | D5: 0.27 | E5: 0.235 | F5: 0.235 | G5: 0.185 | H5: 0.19
A6: ARUNACHAL PRADESH | B6: ARUNACHAL PRADESH | C6: OD Premium | D6: 0.215 | E6: 0.215 | F6: 0.215 | G6: 0.185 | H6: 0.19
A7: ASSAM - 1 GK | B7: ASSAM - KAMRUP (GUWAHATI) | C7: OD Premium | D7: 0.215 | E7: 0.19 | F7: 0.19 | G7: 0.185 | H7: 0.19
A8: ASSAM - 3 R | B8: ASSAM - LOWER | C8: OD Premium | D8: 0.215 | E8: 0.19 | F8: 0.19 | G8: 0.185 | H8: 0.19
A9: ASSAM - 2 U | B9: ASSAM - UPPER | C9: OD Premium | D9: 0.215 | E9: 0.19 | F9: 0.19 | G9: 0.185 | H9: 0.19
A10: BIHAR | B10: BIHAR | C10: OD Premium | D10: 0.28 | E10: 0.21 | F10: 0.26 | G10: 0.185 | H10: 0.19
A11: CHANDIGARH(TRICITY) | B11: CHANDIGARH(TRICITY) | C11: OD Premium | D11: 0.295 | E11: 0.24 | F11: 0.245 | G11: 0.185 | H11: 0.205
A12: CHATTISGARH - 1 RA | B12: CHATTISGARH - RAIPUR | C12: OD Premium | D12: 0 | E12: 0 | F12: 0 | G12: 0 | H12: 0
A13: CHATTISGARH - 2 R | B13: CHATTISGARH - REST | C13: OD Premium | D13: 0 | E13: 0 | F13: 0 | G13: 0 | H13: 0
A14: DELHI - NCR | B14: DELHI - NCR | C14: OD Premium | D14: 0.295 | E14: 0.26 | F14: 0.28 | G14: 0.185 | H14: 0.205
... A50: RAJASTHAN - 3 U | B50: RAJASTHAN - UDAIPUR & SURRONDING | C50: OD Premium | D50: 0.23 | E50: 0.12 | F50: 0.12 | G50: 0.185 | H50: 0.19
A51: #N/A | B51: REST OF INDIA | C51: OD Premium | D51: 0 | E51: 0 | F51: 0 | G51: 0 | H51: 0
A52: SIKKIM | B52: SIKKIM | C52: OD Premium | D52: 0 | E52: 0 | F52: 0 | G52: 0 | H52: 0
A53: TAMIL NADU - 1 C | B53: TAMIL NADU - CHENNAL & PONDICHERRY | C53: OD Premium | D53: 0.23 | E53: 0.19 | F53: 0.19 | G53: 0 | H53: 0.245
A54: TAMIL NADU - 2 CO | B54: TAMIL NADU - REST | C54: OD Premium | D54: 0.14 | E54: 0.145 | F54: 0.14 | G54: 0.145 | H54: 0.19
A55: TELANGANA - 1 H | B55: TELANGANA - HYDERABAD & SURRONDING | C55: OD Premium | D55: 0.28 | E55: 0.21 | F55: 0.27 | G55: 0.185 | H55: 0.225
A56: TELANGANA - 2 R | B56: TELANGANA - REST | C56: OD Premium | D56: 0.28 | E56: 0.2 | F56: 0.25 | G56: 0.185 | H56: 0.205
A57: TRIPURA | B57: TRIPURA | C57: OD Premium | D57: 0 | E57: 0 | F57: 0 | G57: 0 | H57: 0
A58: UTTAR PRADESH - 1 VA | B58: UTTAR PRADESH - LUCKNOW, ALLAHABAD, GORAKHPUR, KANPUR & VARANASI | C58: OD Premium | D58: 0.28 | E58: 0.225 | F58: 0.225 | G58: 0.185 | H58: 0.205
A59: UTTAR PRADESH - 4 R | B59: UTTAR PRADESH - REST | C59: OD Premium | D59: 0.215 | E59: 0.215 | F59: 0.215 | G59: 0.185 | H59: 0.19
A60: #N/A | B60: UTTAR PRADESH - WEST | C60: OD Premium | D60: 0.215 | E60: 0.215 | F60: 0.215 | G60: 0.185 | H60: 0.19
A61: UTTARAKHAND - 1 D | B61: UTTARAKHAND - DEHRADUN | C61: OD Premium | D61: 0.28 | E61: 0.235 | F61: 0.235 | G61: 0.185 | H61: 0.19
A62: UTTARAKHAND - 2 R | B62: UTTARAKHAND - REST | C62: OD Premium | D62: 0.28 | E62: 0.24 | F62: 0.245 | G62: 0.185 | H62: 0.19
A63: WEST BENGAL - 1 K | B63: WEST BENGAL - KOLKATA | C63: OD Premium | D63: 0.28 | E63: 0.21 | F63: 0.26 | G63: 0.185 | H63: 0.19
A64: WEST BENGAL - 2 AD | B64: WEST BENGAL - REST | C64: OD Premium | D64: 0.28 | E64: 0.21 | F64: 0.26 | G64: 0.185 | H64: 0.205
A66: RAJASTHAN - 2 JOK | B66: RAJASTHAN - Kota | C66: OD Premium
A67: RAJASTHAN - 4 R | B67: RAJASTHAN - Rest | C67: OD Premium

Sheet PC Comp
A1: Feb 2025 PAYOUT - PC COMP
A2: Geo Locations | B2: Payout on | C2: Comp - Petrol - NCB / NON NCB | D2: Comp - Diesel / Others - Non NCB | E2: Comp - Diesel / Others - NCB | F2: SOD - NON NCB | G2: SOD - NCB
A3: ANDHRA PRADESH - KRISHNA(VIJAYWADA) | B3: OD Premium | C3: 0.28 | D3: 0.21 | E3: 0.25 | F3: 0.185 | G3: 0.205
A4: ANDHRA PRADESH - REST | B4: OD Premium | C4: 0.27 | D4: 0.21 | E4: 0.25 | F4: 0.185 | G4: 0.19
A5: ANDHRA PRADESH - VISAKHAPATNAM | B5: OD Premium | C5: 0.27 | D5: 0.235 | E5: 0.235 | F5: 0.185 | G5: 0.19
A6: KARNATAKA - BANGALORE | B6: OD Premium | C6: 0.28 | D6: 0.21 | E6: 0.27 | F6: 0.185 | G6: 0.225
A7: KARNATAKA - BANGALORE SURROUNDING | B7: OD Premium | C7: 0.27 | D7: 0.2 | E7: 0.225 | F7: 0.145 | G7: 0.205
A8: KARNATAKA - REST | B8: OD Premium | C8: 0.27 | D8: 0.225 | E8: 0.225 | F8: 0.145 | G8: 0.205
A9: KERALA - ERNAKULAM(COCHIN) | B9: OD Premium | C9: 0.165 | D9: 0.17 | E9: 0.165 | F9: 0.185 | G9: 0.19
A10: KERALA - NORTH | B10: OD Premium | C10: 0.14 | D10: 0.145 | E10: 0.14 | F10: 0.115 | G10: 0.115
A11: KERALA - SOUTH | B11: OD Premium | C11: 0.14 | D11: 0.145 | E11: 0.14 | F11: 0.115 | G11: 0.115
A12: TAMIL NADU - CHENNAL & PONDICHERRY | B12: OD Premium | C12: 0.23 | D12: 0.19 | E12: 0.19 | F12: 0 | G12: 0.245
A13: TAMIL NADU - REST | B13: OD Premium | C13: 0.14 | D13: 0.145 | E13: 0.14 | F13: 0.145 | G13: 0.19
A14: TELANGANA - HYDERABAD & SURRONDING | B14: OD Premium | C14: 0.28 | D14: 0.21 | E14: 0.27 | F14: 0.185 | G14: 0.225
... A61: GUJARAT - VADODARA | B61: OD Premium | C61: 0.28 | D61: 0.235 | E61: 0.28 | F61: 0.185 | G61: 0.19

Sheet PCTP_R_1
C2: Proposed Grid
C3: SATP Petrol | F3: SATP Diesel | H3: CNG
A4: Geo segment New | B4: Geo segment Old | C4: <1000 cc | D4: 1000-1500 cc | E4: >1500 cc | F4: 1000-1500 cc | G4: >1500 cc | H4: <1000 cc | I4: 1000-1500 cc | J4: >1500 cc
A5: ANDHRA PRADESH - 1 KV | B5: ANDHRA PRADESH - KRISHNA(VIJAYWADA) | C5: 0 | D5: 0.26 | E5: 0.4 | F5: 0 | G5: 0 | H5: 0 | I5: 0 | J5: 0.29
A6: ANDHRA PRADESH - 2 V | B6: ANDHRA PRADESH - VISAKHAPATNAM | C6: 0.26 | D6: 0.37 | E6: 0.4 | F6: 0 | G6: 0.2 | H6: 0 | I6: 0 | J6: 0.38
A7: ANDHRA PRADESH - 3 R | B7: ANDHRA PRADESH - REST | C7: 0 | D7: 0 | E7: 0 | F7: 0 | G7: 0 | H7: 0 | I7: 0 | J7: 0
A8: ARUNACHAL PRADESH | B8: ARUNACHAL PRADESH | C8: 0 | D8: 0 | E8: 0 | F8: 0 | G8: 0 | H8: 0.22 | I8: 0.36 | J8: 0.53
A9: ASSAM - 1 GK | B9: ASSAM - KAMRUP (GUWAHATI) | C9: 0 | D9: 0 | E9: 0 | F9: 0 | G9: 0 | H9: 0 | I9: 0 | J9: 0
A10: ASSAM - 2 U | B10: ASSAM - UPPER | C10: 0 | D10: 0 | E10: 0 | F10: 0 | G10: 0 | H10: 0 | I10: 0.14 | J10: 0.39
A11: ASSAM - 3 R | B11: ASSAM - LOWER | C11: 0 | D11: 0 | E11: 0 | F11: 0 | G11: 0 | H11: 0 | I11: 0 | J11: 0
A12: BIHAR | B12: BIHAR | C12: 0.43 | D12: 0.5 | E12: 0.55 | F12: 0 | G12: 0.35 | H12: 0 | I12: 0.29 | J12: 0.49
A13: CHANDIGARH(TRICITY) | B13: CHANDIGARH(TRICITY) | C13: 0.15 | D13: 0.4 | E13: 0.55 | F13: 0 | G13: 0.19 | H13: 0 | I13: 0 | J13: 0.36
A14: CHATTISGARH - 1 RA | B14: CHATTISGARH - RAIPUR | C14: 0 | D14: 0 | E14: 0 | F14: 0 | G14: 0 | H14: 0 | I14: 0 | J14: 0.19
A15: CHATTISGARH - 2 R | B15: CHATTISGARH - REST | C15: 0 | D15: 0 | E15: 0 | F15: 0 | G15: 0 | H15: 0 | I15: 0 | J15: 0
A16: DELHI - NCR | B16: DELHI - NCR | C16: 0.44 | D16: 0.54 | E16: 0.54 | F16: 0.2 | G16: 0.43 | H16: 0.21 | I16: 0.35 | J16: 0.54
... A76: WEST BENGAL - 5 R | B76: WEST BENGAL - REST | C76: 0 | D76: 0 | E76: 0 | F76: 0 | G76: 0 | H76: 0 | I76: 0 | J76: 0

Sheet PCTP_R
A1: March 2025 PAYOUT - PCTP
B2: SATP Petrol | E2: SATP Diesel
A3: Geo Locations | B3: <1000 cc | C3: 1000-1500 cc | D3: >1500 cc | E3: 1000-1500 cc | F3: >1500 cc
A4: ANDHRA PRADESH - KRISHNA(VIJAYWADA) | B4: 0 | C4: 0.25542441 | D4: 0.395 | E4: 0 | F4: 0
A5: ANDHRA PRADESH - REST | B5: 0.37 | C5: 0.37 | D5: 0.37 | E5: 0 | F5: 0.36
A6: ANDHRA PRADESH - VISAKHAPATNAM | B6: 0.37 | C6: 0.37 | D6: 0.37 | E6: 0 | F6: 0.36
A7: ARUNACHAL PRADESH | B7: 0 | C7: 0 | D7: 0 | E7: 0 | F7: 0
A8: ASSAM - KAMRUP (GUWAHATI) | B8: 0 | C8: 0 | D8: 0 | E8: 0 | F8: 0
A9: ASSAM - LOWER | B9: 0 | C9: 0 | D9: 0 | E9: 0 | F9: 0
A10: ASSAM - UPPER | B10: 0 | C10: 0 | D10: 0 | E10: 0 | F10: 0
A11: BIHAR | B11: 0.27 | C11: 0.5 | D11: 0.5 | E11: 0 | F11: 0.35
A12: CHANDIGARH(TRICITY) | B12: 0.145 | C12: 0.26 | D12: 0.515 | E12: 0 | F12: 0.19
A13: CHATTISGARH - RAIPUR | B13: 0 | C13: 0 | D13: 0 | E13: 0 | F13: 0
A14: CHATTISGARH - REST | B14: 0 | C14: 0 | D14: 0 | E14: 0 | F14: 0
A15: DELHI - NCR | B15: 0.365 | C15: 0.52 | D15: 0.5 | E15: 0 | F15: 0.42
... A65: WEST BENGAL - REST | B65: 0 | C65: 0 | D65: 0 | E65: 0 | F65: 0

Sheet PCTP
A1: Feb 2025 PAYOUT - PCTP
A2: Geo Locations | B2: SATP Petrol | E2: SATP Diesel
B3: <1000 cc | C3: 1000-1500 cc | D3: >1500 cc | E3: 1000-1500 cc | F3: >1500 cc
A4: DELHI - NCR | B4: 0.365 | C4: 0.485 | D4: 0.44 | E4: 0 | F4: 0.42 | G4: =VLOOKUP(A4,PCTP_R!$A$4:$A$65,1,0) -> DELHI - NCR
A5: UTTAR PRADESH - LUCKNOW, ALLAHABAD, GORAKHPUR, KANPUR & VARANASI | B5: 0.41 | C5: 0.42 | D5: 0.39 | E5: 0 | F5: 0.4 | G5: =VLOOKUP(A5,PCTP_R!$A$4:$A$65,1,0) -> UTTAR PRADESH - LUCKNOW, ALLAHABAD, GORAKHPUR, KANPUR & VARANASI
A6: KARNATAKA - BANGALORE | B6: 0 | C6: 0.41 | D6: 0.41 | E6: 0 | F6: 0.38 | G6: =VLOOKUP(A6,PCTP_R!$A$4:$A$65,1,0) -> KARNATAKA - BANGALORE
A7: JAMMU & KASHMIR - REST | B7: 0.36 | C7: 0.5 | D7: 0.5 | E7: 0 | F7: 0.4 | G7: =VLOOKUP(A7,PCTP_R!$A$4:$A$65,1,0) -> JAMMU & KASHMIR - REST
A8: MAHARASHTRA - MUMBAI | B8: 0.515 | C8: 0.53 | D8: 0.53 | E8: 0.195 | F8: 0.515 | G8: =VLOOKUP(A8,PCTP_R!$A$4:$A$65,1,0) -> MAHARASHTRA - MUMBAI
A9: UTTARAKHAND - DEHRADUN | B9: 0.4 | C9: 0.5 | D9: 0.47 | E9: 0.245 | F9: 0.4 | G9: =VLOOKUP(A9,PCTP_R!$A$4:$A$65,1,0) -> UTTARAKHAND - DEHRADUN
A10: PUNJAB - LUDHIANA & SURRONDING | B10: 0.23 | C10: 0.5 | D10: 0.45 | E10: 0 | F10: 0 | G10: =VLOOKUP(A10,PCTP_R!$A$4:$A$65,1,0) -> #N/A
A11: MAHARASHTRA - PUNE | B11: 0.515 | C11: 0.53 | D11: 0.53 | E11: 0.195 | F11: 0.515 | G11: =VLOOKUP(A11,PCTP_R!$A$4:$A$65,1,0) -> MAHARASHTRA - PUNE
A12: TELANGANA - HYDERABAD & SURRONDING | B12: 0 | C12: 0.415 | D12: 0.44 | E12: 0 | F12: 0.195 | G12: =VLOOKUP(A12,PCTP_R!$A$4:$A$65,1,0) -> TELANGANA - HYDERABAD & SURRONDING
A13: PUNJAB - AMRITSAR & SURRONDING | B13: 0.23 | C13: 0.5 | D13: 0.45 | E13: 0 | F13: 0 | G13: =VLOOKUP(A13,PCTP_R!$A$4:$A$65,1,0) -> #N/A
A14: WEST BENGAL - KOLKATA | B14: 0.385 | C14: 0.435 | D14: 0.435 | E14: 0.295 | F14: 0.405 | G14: =VLOOKUP(A14,PCTP_R!$A$4:$A$65,1,0) -> WEST BENGAL - KOLKATA
A15: UTTAR PRADESH - REST | B15: 0 | C15: 0 | D15: 0.195 | E15: 0 | F15: 0 | G15: =VLOOKUP(A15,PCTP_R!$A$4:$A$65,1,0) -> UTTAR PRADESH - REST
... A42: NAGALAND | B42: 0 | C42: 0 | D42: 0 | E42: 0 | F42: 0 | G42: =VLOOKUP(A42,PCTP_R!$A$4:$A$65,1,0) -> NAGALAND

Sheet TW Comp
A1: FEB 2025 PAYOUT - TW COMP
A2: Geo Locations | B2: Type (Package 1+1) | C2: Payout % - Net | D2: SOD
A3: ANDHRA PRADESH - KRISHNA(VIJAYWADA) | B3: Bike | C3: 0.235 | D3: 0.025 | E3: =VLOOKUP(A3,'TW Comp_R'!$A$3:$A$64,1,0) -> ANDHRA PRADESH - KRISHNA(VIJAYWADA)
A4: ANDHRA PRADESH - REST | B4: Bike | C4: 0.25 | D4: 0.025 | E4: =VLOOKUP(A4,'TW Comp_R'!$A$3:$A$64,1,0) -> ANDHRA PRADESH - REST
A5: ANDHRA PRADESH - VISAKHAPATNAM | B5: Bike | C5: 0.25 | D5: 0.025 | E5: =VLOOKUP(A5,'TW Comp_R'!$A$3:$A$64,1,0) -> ANDHRA PRADESH - VISAKHAPATNAM
A6: KARNATAKA - BANGALORE | B6: Bike | C6: 0.3 | D6: 0.025 | E6: =VLOOKUP(A6,'TW Comp_R'!$A$3:$A$64,1,0) -> KARNATAKA - BANGALORE
A7: TELANGANA - HYDERABAD & SURRONDING | B7: Bike | C7: 0.235 | D7: 0.025 | E7: =VLOOKUP(A7,'TW Comp_R'!$A$3:$A$64,1,0) -> TELANGANA - HYDERABAD & SURRONDING
A8: TELANGANA - REST | B8: Bike | C8: 0.255 | D8: 0.025 | E8: =VLOOKUP(A8,'TW Comp_R'!$A$3:$A$64,1,0) -> TELANGANA - REST
A9: KARNATAKA - BANGALORE | B9: Scooter | C9: 0.52 | D9: 0.025 | E9: =VLOOKUP(A9,'TW Comp_R'!$A$65:$A$126,1,0) -> KARNATAKA - BANGALORE
A10: UTTAR PRADESH - LUCKNOW, ALLAHABAD, GORAKHPUR, KANPUR & VARANASI | B10: Scooter | C10: 0.5 | D10: 0.025 | E10: =VLOOKUP(A10,'TW Comp_R'!$A$65:$A$126,1,0) -> UTTAR PRADESH - LUCKNOW, ALLAHABAD, GORAKHPUR, KANPUR & VARANASI
A11: TELANGANA - REST | B11: Scooter | C11: 0.45 | D11: 0.025 | E11: =VLOOKUP(A11,'TW Comp_R'!$A$65:$A$126,1,0) -> TELANGANA - REST
A12: BIHAR | B12: Scooter | C12: 0.42 | D12: 0.025 | E12: =VLOOKUP(A12,'TW Comp_R'!$A$65:$A$126,1,0) -> BIHAR
A13: CHANDIGARH(TRICITY) | B13: Scooter | C13: 0.53 | D13: 0.025 | E13: =VLOOKUP(A13,'TW Comp_R'!$A$65:$A$126,1,0) -> CHANDIGARH(TRICITY)
A14: JHARKHAND | B14: Scooter | C14: 0.375 | D14: 0.025 | E14: =VLOOKUP(A14,'TW Comp_R'!$A$65:$A$126,1,0) -> JHARKHAND
A15: CHANDIGARH(TRICITY) | B15: Bike | C15: 0.35 | D15: 0.025 | E15: =VLOOKUP(A15,'TW Comp_R'!$A$3:$A$64,1,0) -> CHANDIGARH(TRICITY)
A16: HIMACHAL PRADESH - BILASPUR, MANDI, SOLAN, SHIMLA & MANALI | B16: Bike | C16: 0.255 | D16: 0.025 | E16: =VLOOKUP(A16,'TW Comp_R'!$A$3:$A$64,1,0) -> HIMACHAL PRADESH - BILASPUR, MANDI, SOLAN, SHIMLA & MANALI
A17: HIMACHAL PRADESH - REST | B17: Bike | C17: 0.235 | D17: 0.025 | E17: =VLOOKUP(A17,'TW Comp_R'!$A$3:$A$64,1,0) -> HIMACHAL PRADESH - REST
A18: JAMMU & KASHMIR - REST | B18: Bike | C18: 0.3 | D18: 0.025 | E18: =VLOOKUP(A18,'TW Comp_R'!$A$3:$A$64,1,0) -> JAMMU & KASHMIR - REST
A19: PUNJAB - AMRITSAR & SURRONDING | B19: Bike | C19: 0.4 | D19: 0.025 | E19: =VLOOKUP(A19,'TW Comp_R'!$A$3:$A$64,1,0) -> PUNJAB - AMRITSAR & SURRONDING
A20: PUNJAB - LUDHIANA & SURRONDING | B20: Bike | C20: 0.4 | D20: 0.025 | E20: =VLOOKUP(A20,'TW Comp_R'!$A$3:$A$64,1,0) -> PUNJAB - LUDHIANA & SURRONDING
A21: UTTAR PRADESH - LUCKNOW, ALLAHABAD, GORAKHPUR, KANPUR & VARANASI | B21: Bike | C21: 0.38 | D21: 0.025 | E21: =VLOOKUP(A21,'TW Comp_R'!$A$3:$A$64,1,0) -> UTTAR PRADESH - LUCKNOW, ALLAHABAD, GORAKHPUR, KANPUR & VARANASI
A22: UTTARAKHAND - DEHRADUN | B22: Bike | C22: 0.285 | D22: 0.025 | E22: =VLOOKUP(A22,'TW Comp_R'!$A$3:$A$64,1,0) -> UTTARAKHAND - DEHRADUN
A23: UTTARAKHAND - REST | B23: Bike | C23: 0.235 | D23: 0.025 | E23: =VLOOKUP(A23,'TW Comp_R'!$A$3:$A$64,1,0) -> UTTARAKHAND - REST
A24: PUNJAB - LUDHIANA & SURRONDING | B24: Scooter | C24: 0.52 | D24: 0.025 | E24: =VLOOKUP(A24,'TW Comp_R'!$A$65:$A$126,1,0) -> PUNJAB - LUDHIANA & SURRONDING
A25: HIMACHAL PRADESH - REST | B25: Scooter | C25: 0.415 | D25: 0.025 | E25: =VLOOKUP(A25,'TW Comp_R'!$A$65:$A$126,1,0) -> HIMACHAL PRADESH - REST
A26: JAMMU & KASHMIR - REST | B26: Scooter | C26: 0.32 | D26: 0.025 | E26: =VLOOKUP(A26,'TW Comp_R'!$A$65:$A$126,1,0) -> JAMMU & KASHMIR - REST
A27: TELANGANA - HYDERABAD & SURRONDING | B27: Scooter | C27: 0.44 | D27: 0.025 | E27: =VLOOKUP(A27,'TW Comp_R'!$A$65:$A$126,1,0) -> TELANGANA - HYDERABAD & SURRONDING
A28: PUNJAB - AMRITSAR & SURRONDING | B28: Scooter | C28: 0.52 | D28: 0.025 | E28: =VLOOKUP(A28,'TW Comp_R'!$A$65:$A$126,1,0) -> PUNJAB - AMRITSAR & SURRONDING
A29: UTTAR PRADESH - REST | B29: Scooter | C29: 0.39 | D29: 0.025 | E29: =VLOOKUP(A29,'TW Comp_R'!$A$65:$A$126,1,0) -> UTTAR PRADESH - REST
A30: ANDHRA PRADESH - KRISHNA(VIJAYWADA) | B30: Scooter | C30: 0.44 | D30: 0.025 | E30: =VLOOKUP(A30,'TW Comp_R'!$A$65:$A$126,1,0) -> ANDHRA PRADESH - KRISHNA(VIJAYWADA)
A31: UTTARAKHAND - REST | B31: Scooter | C31: 0.33 | D31: 0.025 | E31: =VLOOKUP(A31,'TW Comp_R'!$A$65:$A$126,1,0) -> UTTARAKHAND - REST
A32: HIMACHAL PRADESH - BILASPUR, MANDI, SOLAN, SHIMLA & MANALI | B32: Scooter | C32: 0.47 | D32: 0.025 | E32: =VLOOKUP(A32,'TW Comp_R'!$A$65:$A$126,1,0) -> HIMACHAL PRADESH - BILASPUR, MANDI, SOLAN, SHIMLA & MANALI
A33: UTTARAKHAND - DEHRADUN | B33: Scooter | C33: 0.405 | D33: 0.025 | E33: =VLOOKUP(A33,'TW Comp_R'!$A$65:$A$126,1,0) -> UTTARAKHAND - DEHRADUN
A34: WEST BENGAL - REST | B34: Scooter | C34: 0 | D34: 0.025 | E34: =VLOOKUP(A34,'TW Comp_R'!$A$65:$A$126,1,0) -> WEST BENGAL - REST
A35: ASSAM - KAMRUP (GUWAHATI) | B35: Bike | C35: 0 | D35: 0.025 | E35: =VLOOKUP(A35,'TW Comp_R'!$A$3:$A$64,1,0) -> ASSAM - KAMRUP (GUWAHATI)
A36: ASSAM - LOWER | B36: Bike | C36: 0 | D36: 0.025 | E36: =VLOOKUP(A36,'TW Comp_R'!$A$3:$A$64,1,0) -> ASSAM - LOWER
A37: ASSAM - UPPER | B37: Bike | C37: 0 | D37: 0.025 | E37: =VLOOKUP(A37,'TW Comp_R'!$A$3:$A$64,1,0) -> ASSAM - UPPER
A38: BIHAR | B38: Bike | C38: 0.3 | D38: 0.025 | E38: =VLOOKUP(A38,'TW Comp_R'!$A$3:$A$64,1,0) -> BIHAR
A39: CHATTISGARH - RAIPUR | B39: Bike | C39: 0 | D39: 0.025 | E39: =VLOOKUP(A39,'TW Comp_R'!$A$3:$A$64,1,0) -> CHATTISGARH - RAIPUR
A40: CHATTISGARH - REST | B40: Bike | C40: 0 | D40: 0.025 | E40: =VLOOKUP(A40,'TW Comp_R'!$A$3:$A$64,1,0) -> CHATTISGARH - REST
...

Sheet CV COMP_R_1_<7.5T
D2: 0 - 2.5T(4W) | H2: 2.5 - 3.5T | K2: 3.5- 7.5T | N2: PCV 3W | Q2: 3W GCV
A3: New CV Geo Segment 2025 | B3: New Geo Segment 2024 | C3: Old Geo Segment | D3: New | E3: >1 - 5 Years | F3: >5 - 10+ Years | G3: 11+years | H3: New | I3: >1 - 5 Years | J3: >5 - 10+ Years | K3: New | L3: >1 - 5 Years | M3: >5 - 10+ Years | N3: New | O3: >1 - 5 Years | P3: >5 - 10+ Years | Q3: New | R3: >1 - 5 Years | S3: >5 - 10+ Years | T3: 11+years
A4: ANDHRA PRADESH - 1 KV | B4: ANDHRA PRADESH - 1 KV | C4: ANDHRA PRADESH - KRISHNA(VIJAYWADA) | D4: 0.365 | E4: 0.61 | F4: 0.61 | G4: 0.61 | H4: 0 | I4: 0 | J4: 0 | K4: 0 | L4: 0 | M4: 0 | N4: 0.312 | O4: 0.432 | P4: 0.523 | Q4: 0.31 | R4: 0.48 | S4: 0.54 | T4: 0.51
A5: ANDHRA PRADESH - 2 V | B5: ANDHRA PRADESH - 2 V | C5: ANDHRA PRADESH - VISAKHAPATNAM | D5: 0.365 | E5: 0.61 | F5: 0.61 | G5: 0.61 | H5: 0 | I5: 0 | J5: 0 | K5: 0 | L5: 0 | M5: 0.1 | N5: 0.312 | O5: 0.432 | P5: 0.523 | Q5: 0.3 | R5: 0.48 | S5: 0.54 | T5: 0.51
A6: ANDHRA PRADESH - 3 KNO | B6: ANDHRA PRADESH - 3 R | C6: ANDHRA PRADESH - REST | D6: 0.33 | E6: 0.61 | F6: 0.61 | G6: 0.61 | H6: 0 | I6: 0 | J6: 0 | K6: 0 | L6: 0 | M6: 0 | N6: 0.312 | O6: 0.432 | P6: 0.523 | Q6: 0.3210559 | R6: 0.47 | S6: 0.52 | T6: 0.49
A7: ANDHRA PRADESH - 4 R | B7: ANDHRA PRADESH - 3 R | C7: ANDHRA PRADESH - REST | D7: 0 | E7: 0 | F7: 0 | G7: 0 | H7: 0 | I7: 0 | J7: 0 | K7: 0 | L7: 0 | M7: 0 | N7: 0.312 | O7: 0.432 | P7: 0.523 | Q7: 0 | R7: 0 | S7: 0 | T7: 0
A8: ARUNACHAL PRADESH | B8: ARUNACHAL PRADESH | C8: ARUNACHAL PRADESH | D8: 0 | E8: 0 | F8: 0 | G8: 0 | H8: 0 | I8: 0 | J8: 0 | K8: 0 | L8: 0 | M8: 0 | N8: 0.144 | O8: 0.256 | P8: 0.37 | Q8: 0 | R8: 0 | S8: 0 | T8: 0
A9: ASSAM - 1 GK | B9: ASSAM - 1 GK | C9: ASSAM - KAMRUP (GUWAHATI) | D9: 0 | E9: 0 | F9: 0 | G9: 0 | H9: 0 | I9: 0 | J9: 0 | K9: 0 | L9: 0 | M9: 0 | N9: 0 | O9: 0 | P9: 0.18 | Q9: 0 | R9: 0 | S9: 0 | T9: 0
A10: ASSAM - 2 U | B10: ASSAM - 2 U | C10: ASSAM - UPPER | D10: 0.34 | E10: 0.42 | F10: 0.48 | G10: 0.48 | H10: 0 | I10: 0 | J10: 0 | K10: 0 | L10: 0 | M10: 0 | N10: 0 | O10: 0 | P10: 0.18 | Q10: 0.34 | R10: 0.42 | S10: 0.48 | T10: 0.48
A11: ASSAM - 3 R | B11: ASSAM - 3 R | C11: ASSAM - LOWER | D11: 0 | E11: 0 | F11: 0 | G11: 0 | H11: 0 | I11: 0 | J11: 0 | K11: 0 | L11: 0 | M11: 0 | N11: 0 | O11: 0 | P11: 0.18 | Q11: 0 | R11: 0 | S11: 0 | T11: 0
A12: BIHAR | B12: BIHAR | C12: BIHAR | D12: 0.42 | E12: 0.6 | F12: 0.62 | G12: 0.62 | H12: 0 | I12: 0 | J12: 0.4 | K12: 0 | L12: 0 | M12: 0 | N12: 0.32 | O12: 0.384 | P12: 0.478 | Q12: 0.42 | R12: 0.56 | S12: 0.6 | T12: 0.57
A13: CHANDIGARH(TRICITY) | B13: CHANDIGARH(TRICITY) | C13: CHANDIGARH - TRICITY | D13: 0.37 | E13: 0.5 | F13: 0.59 | G13: 0.59029613 | H13: 0 | I13: 0 | J13: 0 | K13: 0 | L13: 0 | M13: 0 | N13: 0.328 | O13: 0.408 | P13: 0.55 | Q13: 0.24 | R13: 0.41 | S13: 0.47 | T13: 0.43
A14: CHATTISGARH - 1 RA | B14: CHATTISGARH - 1 RA | C14: CHATTISGARH - RAIPUR | D14: 0.31 | E14: 0.45 | F14: 0.51 | G14: 0.51 | H14: 0 | I14: 0 | J14: 0 | K14: 0 | L14: 0 | M14: 0 | N14: 0.072 | O14: 0.184 | P14: 0.172 | Q14: 0.28 | R14: 0.45 | S14: 0.5 | T14: 0.46
A15: CHATTISGARH - 2 R | B15: CHATTISGARH - 2 R | C15: CHATTISGARH - REST | D15: 0 | E15: 0 | F15: 0 | G15: 0 | H15: 0 | I15: 0 | J15: 0 | K15: 0 | L15: 0 | M15: 0 | N15: 0.072 | O15: 0.184 | P15: 0.172 | Q15: 0 | R15: 0.22 | S15: 0.29 | T15: 0.23
... A79: WEST BENGAL - 5 R | B79: WEST BENGAL - 5 R | C79: WEST BENGAL - REST | D79: 0 | E79: 0 | F79: 0 | G79: 0 | H79: 0 | I79: 0 | J79: 0 | K79: 0 | L79: 0 | M79: 0 | N79: 0.296 | O79: 0.408 | P79: 0.505 | Q79: 0 | R79: 0 | S79: 0 | T79: 0

Sheet CV COMP_R_1_>7.5T
D2: 12 - 20T | H2: 20 - 40T | L2: 40-43.5T | P2: MISD Tractors
A3: New CV Geo Segment 2025 | B3: New Geo Segment 2024 | C3: Old Geo Segment | D3: New | E3: >1 - 5 Years | F3: >5 - 10 Years | G3: >10-15 years | H3: New | I3: >1 - 5 Years | J3: >5 - 10+ Years | K3: >10-15 years | L3: New | M3: >1 - 5 Years | N3: >5 - 10+ Years | O3: >10-15 years | P3: New | Q3: >1 - 5 Years | R3: >5 - 10+ Years
A4: ANDHRA PRADESH - 1 KV | B4: ANDHRA PRADESH - 1 KV | C4: ANDHRA PRADESH - KRISHNA(VIJAYWADA) | D4: 0 | E4: 0.07 | F4: 0.27 | G4: 0.27 | H4: 0 | I4: 0 | J4: 0.25 | K4: 0.25 | L4: 0 | M4: 0 | N4: 0.25 | O4: 0.25 | P4: 0.28 | Q4: 0.28 | R4: 0.28
A5: ANDHRA PRADESH - 2 V | B5: ANDHRA PRADESH - 2 V | C5: ANDHRA PRADESH - VISAKHAPATNAM | D5: 0.13 | E5: 0.23 | F5: 0.35 | G5: 0.35 | H5: 0.15 | I5: 0.2 | J5: 0.35 | K5: 0.35 | L5: 0 | M5: 0.25 | N5: 0.3 | O5: 0.3 | P5: 0.28 | Q5: 0.28 | R5: 0.28
A6: ANDHRA PRADESH - 3 R | B6: ANDHRA PRADESH - 3 R | C6: ANDHRA PRADESH - REST | D6: 0 | E6: 0 | F6: 0.2 | G6: 0.2 | H6: 0 | I6: 0 | J6: 0.15 | K6: 0.15 | L6: 0 | M6: 0 | N6: 0.18 | O6: 0.18 | P6: 0.28 | Q6: 0.28 | R6: 0.28
A7: ANDHRA PRADESH - 3 R | B7: ANDHRA PRADESH - 3 R | C7: ANDHRA PRADESH - REST | D7: 0 | E7: 0 | F7: 0.2 | G7: 0.2 | H7: 0 | I7: 0 | J7: 0.15 | K7: 0.15 | L7: 0 | M7: 0 | N7: 0.18 | O7: 0.18 | P7: 0.28 | Q7: 0.28 | R7: 0.28
A8: ARUNACHAL PRADESH | B8: ARUNACHAL PRADESH | C8: ARUNACHAL PRADESH | D8: 0 | E8: 0 | F8: 0 | G8: 0 | H8: 0 | I8: 0 | J8: 0 | K8: 0 | L8: 0 | M8: 0 | N8: 0 | O8: 0 | P8: 0 | Q8: 0 | R8: 0
A9: ASSAM | B9: ASSAM - 1 GK | C9: ASSAM - KAMRUP (GUWAHATI) | D9: 0 | E9: 0 | F9: 0 | G9: 0 | H9: 0 | I9: 0 | J9: 0 | K9: 0 | L9: 0 | M9: 0 | N9: 0 | O9: 0 | P9: 0 | Q9: 0 | R9: 0
A10: ASSAM | B10: ASSAM - 2 U | C10: ASSAM - UPPER | D10: 0 | E10: 0 | F10: 0 | G10: 0 | H10: 0 | I10: 0 | J10: 0 | K10: 0 | L10: 0 | M10: 0 | N10: 0 | O10: 0 | P10: 0 | Q10: 0 | R10: 0
A11: ASSAM | B11: ASSAM - 3 R | C11: ASSAM - LOWER | D11: 0 | E11: 0 | F11: 0 | G11: 0 | H11: 0 | I11: 0 | J11: 0 | K11: 0 | L11: 0 | M11: 0 | N11: 0 | O11: 0 | P11: 0 | Q11: 0 | R11: 0
A12: BIHAR | B12: BIHAR | C12: BIHAR | D12: 0.2 | E12: 0.27 | F12: 0.43 | G12: 0.43 | H12: 0.2 | I12: 0.25 | J12: 0.43 | K12: 0.43 | L12: 0.13 | M12: 0.28 | N12: 0.35 | O12: 0.35 | P12: 0.53 | Q12: 0.53 | R12: 0.53
A13: CHANDIGARH(TRICITY) | B13: CHANDIGARH(TRICITY) | C13: CHANDIGARH - TRICITY | D13: 0 | E13: 0 | F13: 0 | G13: 0 | H13: 0 | I13: 0 | J13: 0 | K13: 0 | L13: 0 | M13: 0 | N13: 0 | O13: 0 | P13: 0 | Q13: 0 | R13: 0
A14: CHATTISGARH | B14: CHATTISGARH - 1 RA | C14: CHATTISGARH - RAIPUR | D14: 0 | E14: 0 | F14: 0 | G14: 0.35 | H14: 0 | I14: 0 | J14: 0 | K14: 0 | L14: 0 | M14: 0 | N14: 0 | O14: 0 | P14: 0 | Q14: 0 | R14: 0
A15: CHATTISGARH | B15: CHATTISGARH - 2 R | C15: CHATTISGARH - REST | D15: 0 | E15: 0 | F15: 0 | G15: 0.35 | H15: 0 | I15: 0 | J15: 0 | K15: 0 | L15: 0 | M15: 0 | N15: 0 | O15: 0 | P15: 0 | Q15: 0 | R15: 0
... A79: WEST BENGAL - 2 R | B79: WEST BENGAL - 5 R | C79: WEST BENGAL - REST | D79: 0 | E79: 0.1 | F79: 0.33 | G79: 0.33 | H79: 0.1 | I79: 0.1 | J79: 0.3 | K79: 0.3 | L79: 0 | M79: 0.14 | N79: 0.26 | O79: 0.26 | P79: 0.28 | Q79: 0.28 | R79: 0.28

Sheet CV SATP_R_1 (2)
E2: Upto 2.5 Ton | I2: >2.5-3.5 Ton | J2: >3.5~7.5 Ton | K2: PCV 3W Autorickshaw | R2: Upto 2.5 Ton
E3: GCV 4W | L3: 12 - 20T | O3: 20 - 40T | R3: GCV 3W
A4: New CV Geo Segment 2025_<7.5T | B4: New CV Geo Segment 2025_>7.5T | C4: New Geo Segment 2024 | D4: Old Geo Segment | E4: New | F4: >1 - 5 Years | G4: >5 - 10+ Years | H4: >11 years | L4: New | M4: >1 - 5 Years | N4: >5 - 10+ Years | O4: New | P4: >1 - 5 Years | Q4: >5 - 10+ Years | R4: New | S4: >1 - 5 Years | T4: >5 - 10+ Years | U4: >11 years
A5: ANDHRA PRADESH - 1 KV | B5: ANDHRA PRADESH - 1 KV | C5: ANDHRA PRADESH - 1 KV | D5: ANDHRA PRADESH - KRISHNA(VIJAYWADA) | E5: 0.365 | F5: 0.62 | G5: 0.62 | H5: 0.62 | I5: 0.18 | J5: 0.18 | K5: 0.33 | L5: 0 | M5: 0.2 | N5: 0.35 | O5: 0 | P5: 0.2 | Q5: 0.32 | R5: 0.31 | S5: 0.48 | T5: 0.54 | U5: 0.51
A6: ANDHRA PRADESH - 2 V | B6: ANDHRA PRADESH - 2 V | C6: ANDHRA PRADESH - 2 V | D6: ANDHRA PRADESH - VISAKHAPATNAM | E6: 0.365 | F6: 0.67 | G6: 0.67 | H6: 0.67 | I6: 0.18 | J6: 0.18 | K6: 0.33 | L6: 0 | M6: 0.38 | N6: 0.4 | O6: 0 | P6: 0.2 | Q6: 0.48 | R6: 0.3 | S6: 0.48 | T6: 0.54 | U6: 0.51
A7: ANDHRA PRADESH - 3 KNO | B7: ANDHRA PRADESH - 3 R | C7: ANDHRA PRADESH - 3 R | D7: ANDHRA PRADESH - REST | E7: 0.365 | F7: 0.67 | G7: 0.67 | H7: 0.67 | I7: 0.18 | J7: 0.18 | K7: 0.33 | L7: 0 | M7: 0.1 | N7: 0.29 | O7: 0 | P7: 0.1 | Q7: 0.27 | R7: 0.29 | S7: 0.47 | T7: 0.52 | U7: 0.49
A8: ANDHRA PRADESH - 4 R | B8: ANDHRA PRADESH - 3 R | C8: ANDHRA PRADESH - 3 R | D8: ANDHRA PRADESH - REST | E8: 0.13 | F8: 0.36 | G8: 0.43 | H8: 0.38 | I8: 0.18 | J8: 0.18 | K8: 0.33 | L8: 0 | M8: 0.1 | N8: 0.29 | O8: 0 | P8: 0.1 | Q8: 0.27 | R8: 0 | S8: 0 | T8: 0 | U8: 0
A9: ARUNACHAL PRADESH | B9: ARUNACHAL PRADESH | C9: ARUNACHAL PRADESH | D9: ARUNACHAL PRADESH | E9: 0 | F9: 0 | G9: 0 | H9: 0 | I9: 0.2 | J9: 0.2 | K9: 0.15 | L9: 0 | M9: 0.196 | N9: 0.338 | O9: 0 | P9: 0.1485 | Q9: 0 | R9: 0 | S9: 0 | T9: 0 | U9: 0
A10: ASSAM - 1 GK | B10: ASSAM | C10: ASSAM - 1 GK | D10: ASSAM - KAMRUP (GUWAHATI) | E10: 0 | F10: 0 | G10: 0 | H10: 0 | I10: 0.13 | J10: 0 | K10: 0 | L10: 0 | M10: 0 | N10: 0 | O10: 0 | P10: 0 | Q10: 0 | R10: 0 | S10: 0 | T10: 0 | U10: -0.0043497904
A11: ASSAM - 2 U | B11: ASSAM | C11: ASSAM - 2 U | D11: ASSAM - UPPER | E11: 0.34 | F11: 0.42 | G11: 0.48 | H11: 0.48 | I11: 0.13 | J11: 0 | K11: 0 | L11: 0 | M11: 0 | N11: 0 | O11: 0 | P11: 0 | Q11: 0 | R11: 0.34 | S11: 0.42 | T11: 0.48 | U11: 0.48
A12: ASSAM - 3 R | B12: ASSAM | C12: ASSAM - 3 R | D12: ASSAM - LOWER | E12: 0 | F12: 0 | G12: 0 | H12: 0 | I12: 0.13 | J12: 0 | K12: 0 | L12: 0 | M12: 0 | N12: 0 | O12: 0 | P12: 0 | Q12: 0 | R12: 0 | S12: 0 | T12: 0 | U12: 0
A13: BIHAR | B13: BIHAR | C13: BIHAR | D13: BIHAR | E13: 0.42 | F13: 0.6 | G13: 0.62 | H13: 0.62 | I13: 0.22 | J13: 0.25 | K13: 0.33 | L13: 0.1105 | M13: 0.42 | N13: 0.48 | O13: 0.12 | P13: 0.3 | Q13: 0.35 | R13: 0.42 | S13: 0.56 | T13: 0.6 | U13: 0.57
A14: CHANDIGARH(TRICITY) | B14: CHANDIGARH(TRICITY) | C14: CHANDIGARH(TRICITY) | D14: CHANDIGARH - TRICITY | E14: 0.37 | F14: 0.5 | G14: 0.59 | H14: 0.59029613 | I14: 0.18 | J14: 0.32 | K14: 0.33 | L14: 0 | M14: 0 | N14: 0.0858 | O14: 0 | P14: 0 | Q14: 0 | R14: 0.24 | S14: 0.41 | T14: 0.47 | U14: 0.43
A15: CHATTISGARH - 1 RA | B15: CHATTISGARH | C15: CHATTISGARH - 1 RA | D15: CHATTISGARH - RAIPUR | E15: 0.31 | F15: 0.45 | G15: 0.51 | H15: 0.51 | I15: 0.18 | J15: 0.32 | K15: 0.33 | L15: 0 | M15: 0 | N15: 0 | O15: 0 | P15: 0 | Q15: 0 | R15: 0.28 | S15: 0.45 | T15: 0.5 | U15: 0.46
A16: CHATTISGARH - 2 R | B16: CHATTISGARH | C16: CHATTISGARH - 2 R | D16: CHATTISGARH - REST | E16: 0.27 | F16: 0.388 | G16: 0.4474 | H16: 0.4474 | I16: 0.18 | J16: 0.32 | K16: 0.33 | L16: 0 | M16: 0 | N16: 0 | O16: 0 | P16: 0 | Q16: 0 | R16: 0 | S16: 0 | T16: 0 | U16: 0
... A80: WEST BENGAL - 5 R | B80: WEST BENGAL - 2 R | C80: WEST BENGAL - 5 R | D80: WEST BENGAL - REST | E80: 0.10843501 | F80: 0.28946738 | G80: 0.35785554 | H80: 0.30249938 | I80: 0.28 | J80: 0.32 | K80: 0.33 | L80: 0 | M80: 0.27 | N80: 0.4 | O80: 0 | P80: 0.25 | Q80: 0.4 | R80: 0 | S80: 0.041684017 | T80: 0.142115 | U80: 0.065108344

Sheet CV SATP_R_1
B2: March 2025 PAYOUT - CVSATP
C4: Upto 2.5 Ton | E4: >2.5-3.5 Ton | F4: >3.5~7.5 Ton | G4: PCV 3W Autorickshaw
A5: Geo segment New | B5: Geo segment Old | C5: GCV 4W | D5: GCV 3W
A6: ANDHRA PRADESH - 1 KV | B6: ANDHRA PRADESH - KRISHNA(VIJAYWADA) | C6: 0.33 | D6: 0.18 | E6: 0.18 | F6: 0.18 | G6: 0.33
A7: ANDHRA PRADESH - 2 V | B7: ANDHRA PRADESH - VISAKHAPATNAM | C7: 0.33 | D7: 0.18 | E7: 0.18 | F7: 0.18 | G7: 0.33
A8: ANDHRA PRADESH - 3 R | B8: ANDHRA PRADESH - REST | C8: 0.33 | D8: 0.18 | E8: 0.18 | F8: 0.18 | G8: 0.33
A9: ARUNACHAL PRADESH | B9: ARUNACHAL PRADESH | C9: 0.2 | D9: 0.2 | E9: 0.2 | F9: 0.2 | G9: 0.15
A10: ASSAM - 1 GK | B10: ASSAM - KAMRUP (GUWAHATI) | C10: 0.28 | D10: 0.13 | E10: 0.13 | F10: 0 | G10: 0
A11: ASSAM - 2 U | B11: ASSAM - UPPER | C11: 0.28 | D11: 0.13 | E11: 0.13 | F11: 0 | G11: 0
A12: ASSAM - 3 R | B12: ASSAM - LOWER | C12: 0.28 | D12: 0.13 | E12: 0.13 | F12: 0 | G12: 0
A13: BIHAR | B13: BIHAR | C13: 0.33 | D13: 0.33 | E13: 0.22 | F13: 0.25 | G13: 0.33
A14: CHANDIGARH(TRICITY) | B14: CHANDIGARH(TRICITY) | C14: 0.33 | D14: 0.13 | E14: 0.18 | F14: 0.32 | G14: 0.33
A15: CHATTISGARH - 1 RA | B15: CHATTISGARH - RAIPUR | C15: 0.33 | D15: 0.13 | E15: 0.18 | F15: 0.32 | G15: 0.33
A16: CHATTISGARH - 2 R | B16: CHATTISGARH - REST | C16: 0.33 | D16: 0.13 | E16: 0.18 | F16: 0.32 | G16: 0.33
A17: DELHI - NCR | B17: DELHI - NCR | C17: 0.33 | D17: 0.18 | E17: 0.18 | F17: 0.08 | G17: 0.61
... A77: WEST BENGAL - 5 R | B77: WEST BENGAL - REST | C77: 0.33 | D77: 0.28 | E77: 0.28 | F77: 0.32 | G77: 0.33

Sheet TW Comp_R_1
C2: Bikes | G2: Scooter
A3: Geo segment New | B3: Geo segment Old | C3: < 75 CC | D3: >75-150 CC | E3: > 150-350 CC | F3: > 350 CC | G3: < 75 CC | H3: >75-150 CC
A4: ANDHRA PRADESH - 1 KV | B4: ANDHRA PRADESH - KRISHNA(VIJAYWADA) | C4: 0.45 | D4: 0.43479437 | E4: 0.45 | F4: 0.38 | G4: 0.54 | H4: 0.54
A5: ANDHRA PRADESH - 2 V | B5: ANDHRA PRADESH - VISAKHAPATNAM | C5: 0 | D5: 0 | E5: 0 | F5: 0 | G5: 0 | H5: 0
A6: ANDHRA PRADESH - 3 R | B6: ANDHRA PRADESH - REST | C6: 0.45 | D6: 0.27 | E6: 0.32 | F6: 0.45 | G6: 0.5 | H6: 0.5
A7: ARUNACHAL PRADESH | B7: ARUNACHAL PRADESH | C7: 0 | D7: 0 | E7: 0 | F7: 0 | G7: 0 | H7: 0
A8: ASSAM - 1 GK | B8: ASSAM - KAMRUP (GUWAHATI) | C8: 0 | D8: 0 | E8: 0 | F8: 0 | G8: 0 | H8: 0
A9: ASSAM - 2 U | B9: ASSAM - UPPER | C9: 0 | D9: 0 | E9: 0 | F9: 0 | G9: 0 | H9: 0
A10: ASSAM - 3 R | B10: ASSAM - LOWER | C10: 0 | D10: 0 | E10: 0 | F10: 0 | G10: 0 | H10: 0
A11: BIHAR | B11: BIHAR | C11: 0 | D11: 0 | E11: 0 | F11: 0 | G11: 0.55 | H11: 0.55
A12: CHANDIGARH(TRICITY) | B12: CHANDIGARH(TRICITY) | C12: 0.36575105 | D12: 0.24007669 | E12: 0.32758262 | F12: 0.389 | G12: 0.55 | H12: 0.55
A13: CHATTISGARH - 1 RA | B13: CHATTISGARH - RAIPUR | C13: 0 | D13: 0 | E13: 0 | F13: 0 | G13: 0.47 | H13: 0.47
A14: CHATTISGARH - 2 R | B14: CHATTISGARH - REST | C14: 0 | D14: 0 | E14: 0 | F14: 0 | G14: 0 | H14: 0
A15: DELHI - NCR | B15: DELHI - NCR | C15: 0.32 | D15: 0.15 | E15: 0.23 | F15: 0.37 | G15: 0.55 | H15: 0.51
... A75: WEST BENGAL - 5 R | B75: WEST BENGAL - REST | C75: 0 | D75: 0 | E75: 0 | F75: 0 | G75: 0 | H75: 0

Sheet TW Comp_R
A1: March 2025 PAYOUT - TW COMP
A2: Geo Locations | B2: Type (Package 1+1) | C2: Payout % - Net | D2: SOD
A3: ANDHRA PRADESH - KRISHNA(VIJAYWADA) | B3: Bike | C3: 0.235 | D3: 0.025
A4: ANDHRA PRADESH - REST | B4: Bike | C4: 0.25 | D4: 0.025
A5: ANDHRA PRADESH - VISAKHAPATNAM | B5: Bike | C5: 0.25 | D5: 0.025
A6: ARUNACHAL PRADESH | B6: Bike | C6: 0 | D6: 0
A7: ASSAM - KAMRUP (GUWAHATI) | B7: Bike | C7: 0 | D7: 0.025
A8: ASSAM - LOWER | B8: Bike | C8: 0 | D8: 0.025
A9: ASSAM - UPPER | B9: Bike | C9: 0 | D9: 0.025
A10: BIHAR | B10: Bike | C10: 0.3 | D10: 0.025
A11: CHANDIGARH(TRICITY) | B11: Bike | C11: 0.35 | D11: 0.025
A12: CHATTISGARH - RAIPUR | B12: Bike | C12: 0 | D12: 0.025
A13: CHATTISGARH - REST | B13: Bike | C13: 0 | D13: 0.025
A14: DELHI - NCR | B14: Bike | C14: 0 | D14: 0
... A126: WEST BENGAL - REST | B126: Scooter | C126: 0 | D126: 0.025

Sheet CV COMP_R
B2: 0 - 2.5T | E2: 2.5 - 3.5T | H2: 3.5- 7.5T | K2: 12 - 20T | N2: 20 - 43T | Q2: PCV 3W | T2: MISD Tractors
A3: Geo Location - New | B3: New | C3: >1 - 5 Years | D3: >5 - 10+ Years | E3: New | F3: >1 - 5 Years | G3: >5 - 10+ Years | H3: New | I3: >1 - 5 Years | J3: >5 - 10+ Years | K3: New | L3: >1 - 5 Years | M3: >5 - 10+ Years | N3: New | O3: >1 - 5 Years | P3: >5 - 10+ Years | Q3: New | R3: >1 - 5 Years | S3: >5 - 10+ Years | T3: New | U3: >1 - 5 Years | V3: >5 - 10+ Years
A4: ANDHRA PRADESH - KRISHNA(VIJAYWADA) | B4: 0.365 | C4: 0.47 | D4: 0.55 | E4: 0 | F4: 0 | G4: 0 | H4: 0 | I4: 0 | J4: 0 | K4: 0 | L4: 0 | M4: 0 | N4: 0 | O4: 0 | P4: 0 | Q4: 0.312 | R4: 0.432 | S4: 0.523 | T4: 0.28 | U4: 0.28 | V4: 0.28
A5: ANDHRA PRADESH - REST | B5: 0.365 | C5: 0.47 | D5: 0.55 | E5: 0 | F5: 0 | G5: 0 | H5: 0 | I5: 0 | J5: 0 | K5: 0 | L5: 0 | M5: 0 | N5: 0 | O5: 0 | P5: 0 | Q5: 0.312 | R5: 0.432 | S5: 0.523 | T5: 0.28 | U5: 0.28 | V5: 0.28
A6: ANDHRA PRADESH - VISAKHAPATNAM | B6: 0.365 | C6: 0.47 | D6: 0.55 | E6: 0 | F6: 0 | G6: 0 | H6: 0 | I6: 0 | J6: 0.1 | K6: 0 | L6: 0 | M6: 0 | N6: 0 | O6: 0 | P6: 0 | Q6: 0.312 | R6: 0.432 | S6: 0.523 | T6: 0.28 | U6: 0.28 | V6: 0.28
A7: ARUNACHAL PRADESH | B7: 0.235 | C7: 0.271 | D7: 0.34 | E7: 0 | F7: 0 | G7: 0 | H7: 0.397 | I7: 0.397 | J7: 0.428 | K7: 0 | L7: 0.196 | M7: 0.338 | N7: 0 | O7: 0.1485 | P7: 0 | Q7: 0.144 | R7: 0.256 | S7: 0.37 | T7: 0 | U7: 0 | V7: 0
A8: ASSAM - KAMRUP (GUWAHATI) | B8: 0.383 | C8: 0.428 | D8: 0.4868 | E8: 0 | F8: 0 | G8: 0 | H8: 0 | I8: 0 | J8: 0 | K8: 0 | L8: 0 | M8: 0 | N8: 0 | O8: 0 | P8: 0 | Q8: 0 | R8: 0 | S8: 0.271 | T8: 0 | U8: 0 | V8: 0
A9: ASSAM - LOWER | B9: 0.383 | C9: 0.428 | D9: 0.4868 | E9: 0 | F9: 0 | G9: 0 | H9: 0 | I9: 0 | J9: 0 | K9: 0 | L9: 0 | M9: 0 | N9: 0 | O9: 0 | P9: 0 | Q9: 0 | R9: 0 | S9: 0.271 | T9: 0 | U9: 0 | V9: 0
A10: ASSAM - UPPER | B10: 0.383 | C10: 0.428 | D10: 0.4868 | E10: 0 | F10: 0 | G10: 0 | H10: 0 | I10: 0 | J10: 0 | K10: 0 | L10: 0 | M10: 0 | N10: 0 | O10: 0 | P10: 0 | Q10: 0 | R10: 0 | S10: 0.271 | T10: 0 | U10: 0 | V10: 0
A11: BIHAR | B11: 0.5 | C11: 0.572 | D11: 0.62 | E11: 0 | F11: 0 | G11: 0.4 | H11: 0.306 | I11: 0.376 | J11: 0.468 | K11: 0.1105 | L11: 0.2 | M11: 0.31 | N11: 0.12 | O11: 0.0725 | P11: 0.22 | Q11: 0.32 | R11: 0.384 | S11: 0.478 | T11: 0.505 | U11: 0.505 | V11: 0.5125
A12: CHANDIGARH(TRICITY) | B12: 0.43 | C12: 0.5 | D12: 0.59 | E12: 0 | F12: 0 | G12: 0 | H12: 0 | I12: 0 | J12: 0.292 | K12: 0 | L12: 0 | M12: 0.0858 | N12: 0 | O12: 0 | P12: 0 | Q12: 0.328 | R12: 0.408 | S12: 0.505 | T12: 0 | U12: 0 | V12: 0
A13: CHATTISGARH - RAIPUR | B13: 0.338 | C13: 0.45 | D13: 0.51 | E13: 0 | F13: 0 | G13: 0 | H13: 0.117 | I13: 0.201 | J13: 0.324 | K13: 0 | L13: 0 | M13: 0 | N13: 0 | O13: 0 | P13: 0 | Q13: 0.072 | R13: 0.184 | S13: 0.172 | T13: 0 | U13: 0 | V13: 0
A14: CHATTISGARH - REST | B14: 0.28 | C14: 0.388 | D14: 0.4474 | E14: 0 | F14: 0 | G14: 0.3 | H14: 0.117 | I14: 0.201 | J14: 0.324 | K14: 0 | L14: 0 | M14: 0 | N14: 0 | O14: 0 | P14: 0 | Q14: 0.072 | R14: 0.184 | S14: 0.172 | T14: 0 | U14: 0 | V14: 0
A15: DELHI - NCR | B15: 0.365 | C15: 0.49 | D15: 0.57 | E15: 0 | F15: 0 | G15: 0 | H15: 0 | I15: 0 | J15: 0 | K15: 0 | L15: 0 | M15: 0 | N15: 0 | O15: 0 | P15: 0 | Q15: 0.512 | R15: 0.55 | S15: 0.61 | T15: 0 | U15: 0 | V15: 0
... A65: WEST BENGAL - REST | B65: 0.32 | C65: 0.55 | D65: 0.62 | E65: 0 | F65: 0 | G65: 0 | H65: 0 | I65: 0 | J65: 0 | K65: 0 | L65: 0 | M65: 0 | N65: 0 | O65: 0 | P65: 0 | Q65: 0.296 | R65: 0.408 | S65: 0.505 | T65: 0.28 | U65: 0.28 | V65: 0.28

Sheet CV Comp
B1: FEB 2025 CV
B2: Geo Segments | C2: Geo Segment CV | D2: 0 - 2.6T | G2: 2.6 - 4T | J2: 4 - 7.5T | M2: 12 - 20T | P2: 20 - 43T | S2: PCV 3W | V2: MISD Tractors
D3: New | E3: >1 - 5 Years | F3: >5 - 10+ Years | G3: New | H3: >1 - 5 Years | I3: >5 - 10+ Years | J3: New | K3: >1 - 5 Years | L3: >5 - 10+ Years | M3: New | N3: >1 - 5 Years | O3: >5 - 10+ Years | P3: New | Q3: >1 - 5 Years | R3: >5 - 10+ Years | S3: New | T3: >1 - 5 Years | U3: >5 - 10+ Years | V3: New | W3: >1 - 5 Years | X3: >5 - 10+ Years
A4: =VLOOKUP(B4,'CV COMP_R'!$A:$A,1,0) -> ANDHRA PRADESH - KRISHNA(VIJAYWADA) | B4: ANDHRA PRADESH - KRISHNA(VIJAYWADA) | C4: ANDHRA PRADESH | D4: 0.307 | E4: 0.415 | F4: 0.47 | G4: 0 | H4: 0 | I4: 0 | J4: 0 | K4: 0 | L4: 0 | M4: 0 | N4: 0 | O4: 0 | P4: 0 | Q4: 0 | R4: 0 | S4: 0.312 | T4: 0.432 | U4: 0.523 | V4: 0.28 | W4: 0.28 | X4: 0.28
A5: =VLOOKUP(B5,'CV COMP_R'!$A:$A,1,0) -> ANDHRA PRADESH - REST | B5: ANDHRA PRADESH - REST | C5: ANDHRA PRADESH | D5: 0.307 | E5: 0.415 | F5: 0.47 | G5: 0 | H5: 0 | I5: 0 | J5: 0 | K5: 0 | L5: 0 | M5: 0 | N5: 0 | O5: 0 | P5: 0 | Q5: 0 | R5: 0 | S5: 0.312 | T5: 0.432 | U5: 0.523 | V5: 0.28 | W5: 0.28 | X5: 0.28
A6: =VLOOKUP(B6,'CV COMP_R'!$A:$A,1,0) -> ANDHRA PRADESH - VISAKHAPATNAM | B6: ANDHRA PRADESH - VISAKHAPATNAM | C6: ANDHRA PRADESH | D6: 0.307 | E6: 0.415 | F6: 0.47 | G6: 0 | H6: 0 | I6: 0 | J6: 0 | K6: 0 | L6: 0.1 | M6: 0 | N6: 0 | O6: 0 | P6: 0 | Q6: 0 | R6: 0 | S6: 0.312 | T6: 0.432 | U6: 0.523 | V6: 0.28 | W6: 0.28 | X6: 0.28
A7: =VLOOKUP(B7,'CV COMP_R'!$A:$A,1,0) -> KARNATAKA - BANGALORE | B7: KARNATAKA - BANGALORE | C7: KARNATAKA - BANGALORE | D7: 0.28 | E7: 0.42 | F7: 0.49 | G7: 0 | H7: 0 | I7: 0 | J7: 0 | K7: 0 | L7: 0 | M7: 0 | N7: 0 | O7: 0 | P7: 0 | Q7: 0 | R7: 0 | S7: 0 | T7: 0.168 | U7: 0.334 | V7: 0 | W7: 0 | X7: 0
A8: =VLOOKUP(B8,'CV COMP_R'!$A:$A,1,0) -> KARNATAKA - BANGALORE SURROUNDING | B8: KARNATAKA - BANGALORE SURROUNDING | C8: KARNATAKA - BANGALORE | D8: 0.1 | E8: 0.3 | F8: 0.42 | G8: 0 | H8: 0 | I8: 0 | J8: 0 | K8: 0 | L8: 0 | M8: 0 | N8: 0 | O8: 0 | P8: 0 | Q8: 0 | R8: 0 | S8: 0.136 | T8: 0.112 | U8: 0.271 | V8: 0 | W8: 0 | X8: 0
A9: =VLOOKUP(B9,'CV COMP_R'!$A:$A,1,0) -> KARNATAKA - REST | B9: KARNATAKA - REST | C9: KARNATAKA - REST | D9: 0.1 | E9: 0.3 | F9: 0.42 | G9: 0 | H9: 0 | I9: 0 | J9: 0 | K9: 0 | L9: 0 | M9: 0 | N9: 0 | O9: 0 | P9: 0 | Q9: 0 | R9: 0 | S9: 0.136 | T9: 0.112 | U9: 0.271 | V9: 0 | W9: 0 | X9: 0
A10: =VLOOKUP(B10,'CV COMP_R'!$A:$A,1,0) -> TELANGANA - HYDERABAD & SURRONDING | B10: TELANGANA - HYDERABAD & SURRONDING | C10: TELANGANA | D10: 0.262 | E10: 0.343 | F10: 0.5032 | G10: 0 | H10: 0 | I10: 0 | J10: 0 | K10: 0.201 | L10: 0.284 | M10: 0 | N10: 0 | O10: 0 | P10: 0 | Q10: 0 | R10: 0 | S10: 0.376 | T10: 0.408 | U10: 0.514 | V10: 0 | W10: 0 | X10: 0
A11: =VLOOKUP(B11,'CV COMP_R'!$A:$A,1,0) -> TELANGANA - REST | B11: TELANGANA - REST | C11: TELANGANA | D11: 0.262 | E11: 0.343 | F11: 0.5032 | G11: 0 | H11: 0 | I11: 0.3 | J11: 0 | K11: 0.201 | L11: 0.284 | M11: 0 | N11: 0 | O11: 0 | P11: 0 | Q11: 0 | R11: 0 | S11: 0.376 | T11: 0.408 | U11: 0.514 | V11: 0 | W11: 0 | X11: 0
A12: =VLOOKUP(B12,'CV COMP_R'!$A:$A,1,0) -> GOA | B12: GOA | C12: GOA | D12: 0.631 | E12: 0.65 | F12: 0.65 | G12: 0 | H12: 0 | I12: 0 | J12: 0.383 | K12: 0.397 | L12: 0.428 | M12: 0.2815 | N12: 0.3955 | O12: 0.3 | P12: 0.2435 | Q12: 0.4145 | R12: 0.34 | S12: 0.56 | T12: 0.52 | U12: 0.55 | V12: 0 | W12: 0 | X12: 0
A13: =VLOOKUP(B13,'CV COMP_R'!$A:$A,1,0) -> MADHYA PRADESH - BHOPAL & INDORE | B13: MADHYA PRADESH - BHOPAL & INDORE | C13: MADHYA PRADESH | D13: 0.217 | E13: 0.37 | F13: 0.3544 | G13: 0 | H13: 0 | I13: 0 | J13: 0 | K13: 0 | L13: 0 | M13: 0 | N13: 0 | O13: 0 | P13: 0 | Q13: 0 | R13: 0 | S13: 0 | T13: 0.264 | U13: 0.379 | V13: 0 | W13: 0 | X13: 0
A14: =VLOOKUP(B14,'CV COMP_R'!$A:$A,1,0) -> MADHYA PRADESH - GWALIOR & JABALPUR | B14: MADHYA PRADESH - GWALIOR & JABALPUR | C14: MADHYA PRADESH | D14: 0.217 | E14: 0.37 | F14: 0.3544 | G14: 0 | H14: 0 | I14: 0 | J14: 0 | K14: 0 | L14: 0 | M14: 0 | N14: 0 | O14: 0 | P14: 0 | Q14: 0 | R14: 0 | S14: 0 | T14: 0.264 | U14: 0.379 | V14: 0 | W14: 0 | X14: 0
A15: =VLOOKUP(B15,'CV COMP_R'!$A:$A,1,0) -> MADHYA PRADESH - REST | B15: MADHYA PRADESH - REST | C15: MADHYA PRADESH | D15: 0.217 | E15: 0.37 | F15: 0.3544 | G15: 0 | H15: 0 | I15: 0 | J15: 0 | K15: 0 | L15: 0 | M15: 0 | N15: 0 | O15: 0 | P15: 0 | Q15: 0 | R15: 0 | S15: 0 | T15: 0.264 | U15: 0.379 | V15: 0 | W15: 0 | X15: 0
... A42: =VLOOKUP(B42,'CV COMP_R'!$A:$A,1,0) -> WEST BENGAL - REST | B42: WEST BENGAL - REST | C42: WEST BENGAL | D42: 0.262 | E42: 0.496 | F42: 0.559 | G42: 0 | H42: 0 | I42: 0 | J42: 0 | K42: 0 | L42: 0 | M42: 0 | N42: 0 | O42: 0 | P42: 0 | Q42: 0 | R42: 0 | S42: 0.296 | T42: 0.408 | U42: 0.505 | V42: 0.28 | W42: 0.28 | X42: 0.28

Sheet CV SATP_R
A1: March 2025 PAYOUT_CV SATP
A4: Segement | B4: Upto 2.5 Ton | D4: >2.5~3.5 T | E4: >3.5~7.5 T | F4: PCV 3W Autorickshaw
A5: Geo Location - New | B5: GCV 4W | C5: GCV 3W
A6: ANDHRA PRADESH - KRISHNA(VIJAYWADA) | B6: 0.33 | C6: 0.18 | D6: 0.18 | E6: 0.18 | F6: 0.33
A7: ANDHRA PRADESH - REST | B7: 0.33 | C7: 0.18 | D7: 0.18 | E7: 0.18 | F7: 0.33
A8: ANDHRA PRADESH - VISAKHAPATNAM | B8: 0.33 | C8: 0.18 | D8: 0.18 | E8: 0.18 | F8: 0.33
A9: ARUNACHAL PRADESH | B9: 0.2 | C9: 0.2 | D9: 0.2 | E9: 0.2 | F9: 0.15
A10: ASSAM - KAMRUP (GUWAHATI) | B10: 0.28 | C10: 0.13 | D10: 0.13 | E10: 0 | F10: 0
A11: ASSAM - LOWER | B11: 0.28 | C11: 0.13 | D11: 0.13 | E11: 0 | F11: 0
A12: ASSAM - UPPER | B12: 0.28 | C12: 0.13 | D12: 0.13 | E12: 0 | F12: 0
A13: BIHAR | B13: 0.33 | C13: 0.33 | D13: 0.22 | E13: 0.25 | F13: 0.33
A14: CHANDIGARH(TRICITY) | B14: 0.33 | C14: 0.13 | D14: 0.18 | E14: 0.32 | F14: 0.33
A15: CHATTISGARH - RAIPUR | B15: 0.33 | C15: 0.13 | D15: 0.18 | E15: 0.32 | F15: 0.33
A16: CHATTISGARH - REST | B16: 0.33 | C16: 0.13 | D16: 0.18 | E16: 0.32 | F16: 0.33
A17: DELHI - NCR | B17: 0.33 | C17: 0.18 | D17: 0.18 | E17: 0.08 | F17: 0.61
... A67: WEST BENGAL - REST | B67: 0.33 | C67: 0.28 | D67: 0.28 | E67: 0.32 | F67: 0.33

Sheet CV SATP
A1: FEB 2025 PAYOUT_CV SATP
A2: Segement | B2: Upto 2.5 Ton | D2: >2.5~3.5 T | E2: >3.5~7.5 T | F2: PCV 3W Autorickshaw
A3: Geo Location - New | B3: GCV 4W | C3: GCV 3W
A4: CHANDIGARH(TRICITY) | B4: 0.33 | C4: 0.13 | D4: 0.18 | E4: 0.32 | F4: 0.33 | G4: =VLOOKUP(A4,'CV SATP_R'!$A$6:$A$67,1,0) -> CHANDIGARH(TRICITY)
A5: DELHI - NCR | B5: 0.33 | C5: 0.18 | D5: 0.18 | E5: 0.08 | F5: 0.61 | G5: =VLOOKUP(A5,'CV SATP_R'!$A$6:$A$67,1,0) -> DELHI - NCR
A6: HIMACHAL PRADESH - BILASPUR, MANDI, SOLAN, SHIMLA & MANALI | B6: 0.33 | C6: 0.28 | D6: 0.33 | E6: 0.28 | F6: 0.33 | G6: =VLOOKUP(A6,'CV SATP_R'!$A$6:$A$67,1,0) -> HIMACHAL PRADESH - BILASPUR, MANDI, SOLAN, SHIMLA & MANALI
A7: HIMACHAL PRADESH - REST | B7: 0.33 | C7: 0.28 | D7: 0.33 | E7: 0.4 | F7: 0.33 | G7: =VLOOKUP(A7,'CV SATP_R'!$A$6:$A$67,1,0) -> HIMACHAL PRADESH - REST
A8: JAMMU & KASHMIR - JAMMU | B8: 0.33 | C8: 0.28 | D8: 0.33 | E8: 0.4 | F8: 0 | G8: =VLOOKUP(A8,'CV SATP_R'!$A$6:$A$67,1,0) -> JAMMU & KASHMIR - JAMMU
A9: JAMMU & KASHMIR - REST | B9: 0.33 | C9: 0.28 | D9: 0.33 | E9: 0.4 | F9: 0 | G9: =VLOOKUP(A9,'CV SATP_R'!$A$6:$A$67,1,0) -> JAMMU & KASHMIR - REST
A10: PUNJAB - AMRITSAR & SURRONDING | B10: 0.33 | C10: 0.18 | D10: 0.18 | E10: 0.18 | F10: 0.33 | G10: =VLOOKUP(A10,'CV SATP_R'!$A$6:$A$67,1,0) -> PUNJAB - AMRITSAR & SURRONDING
A11: PUNJAB - LUDHIANA & SURRONDING | B11: 0.33 | C11: 0.18 | D11: 0.18 | E11: 0.18 | F11: 0.33 | G11: =VLOOKUP(A11,'CV SATP_R'!$A$6:$A$67,1,0) -> PUNJAB - LUDHIANA & SURRONDING
A12: RAJASTHAN - JAIPUR | B12: 0.08 | C12: 0.1 | D12: 0 | E12: 0 | F12: 0.15 | G12: =VLOOKUP(A12,'CV SATP_R'!$A$6:$A$67,1,0) -> RAJASTHAN - JAIPUR
A13: RAJASTHAN - JAIPUR SURRONDING | B13: 0.08 | C13: 0.1 | D13: 0 | E13: 0 | F13: 0.15 | G13: =VLOOKUP(A13,'CV SATP_R'!$A$6:$A$67,1,0) -> RAJASTHAN - JAIPUR SURRONDING
A14: RAJASTHAN - REST | B14: 0.08 | C14: 0.1 | D14: 0 | E14: 0 | F14: 0.025 | G14: =VLOOKUP(A14,'CV SATP_R'!$A$6:$A$67,1,0) -> RAJASTHAN - REST
A15: RAJASTHAN - UDAIPUR & SURRONDING | B15: 0.18 | C15: 0.1 | D15: 0 | E15: 0 | F15: 0.15 | G15: =VLOOKUP(A15,'CV SATP_R'!$A$6:$A$67,1,0) -> RAJASTHAN - UDAIPUR & SURRONDING
... A20: UTTARAKHAND - REST | B20: 0.33 | C20: 0.33 | D20: 0.18 | E20: 0.28 | F20: 0.28 | G20: =VLOOKUP(A20,'CV SATP_R'!$A$6:$A$67,1,0) -> UTTARAKHAND - REST

Sheet TW SATP_R_1
B2: Aug 2025 PAYOUT - TWSATP
I3: Bikes
C4: Bikes | G4: Scooter | I4: SATP Payout
A5: Geo segment New | B5: Geo segment Old | C5: < 75 CC | D5: >75-150 CC | E5: > 150-350 CC | F5: > 350 CC | G5: < 150 CC | I5: < 75 CC | J5: 75-150 CC | K5: 150-350 CC | L5: > 350 CC
A6: ANDHRA PRADESH - 1 KV | B6: ANDHRA PRADESH - KRISHNA(VIJAYWADA) | C6: 0.5 | D6: 0.53 | E6: 0.5 | F6: 0.32 | G6: 0.63 | I6: 0.41 | J6: 0.41 | K6: 0.28 | L6: 0.28
A7: ANDHRA PRADESH - 2 V | B7: ANDHRA PRADESH - VISAKHAPATNAM | C7: 0.5 | D7: 0.53 | E7: 0.5 | F7: 0.32 | G7: 0.63 | I7: #N/A | J7: #N/A | K7: #N/A | L7: #N/A
A8: ANDHRA PRADESH - 3 R | B8: ANDHRA PRADESH - REST | C8: 0 | D8: 0 | E8: 0.25 | F8: 0.4 | G8: 0.63 | I8: 0.389 | J8: 0.2684597 | K8: 0.32211798 | L8: 0.389
A9: ARUNACHAL PRADESH | B9: ARUNACHAL PRADESH | C9: 0 | D9: 0 | E9: 0 | F9: 0 | G9: 0 | I9: 0 | J9: 0 | K9: 0 | L9: 0
A10: ASSAM - 1 GK | B10: ASSAM - KAMRUP (GUWAHATI) | C10: 0 | D10: 0 | E10: 0 | F10: 0 | G10: 0 | I10: #N/A | J10: #N/A | K10: #N/A | L10: #N/A
A11: ASSAM - 2 U | B11: ASSAM - UPPER | C11: 0 | D11: 0 | E11: 0 | F11: 0 | G11: 0 | I11: 0 | J11: 0 | K11: 0 | L11: 0
A12: ASSAM - 3 R | B12: ASSAM - LOWER | C12: 0 | D12: 0 | E12: 0 | F12: 0 | G12: 0 | I12: 0 | J12: 0 | K12: 0 | L12: 0
A13: BIHAR | B13: BIHAR | C13: 0.5 | D13: 0.55 | E13: 0.5 | F13: 0.55 | G13: 0.6 | I13: 0 | J13: 0 | K13: 0 | L13: 0
A14: CHANDIGARH(TRICITY) | B14: CHANDIGARH(TRICITY) | C14: 0.44 | D14: 0.44 | E14: 0.44 | F14: 0.4 | G14: 0.58 | I14: 0.36575105 | J14: 0.24007669 | K14: 0.32758262 | L14: 0.389
A15: CHATTISGARH - 1 RA | B15: CHATTISGARH - RAIPUR | C15: 0.5 | D15: 0.4 | E15: 0.46 | F15: 0.5 | G15: 0.5 | I15: 0 | J15: 0 | K15: 0 | L15: 0
A16: CHATTISGARH - 2 R | B16: CHATTISGARH - REST | C16: 0 | D16: 0 | E16: 0 | F16: 0 | G16: 0 | I16: 0 | J16: 0 | K16: 0 | L16: 0
A17: DELHI - NCR | B17: DELHI - NCR | C17: 0.5 | D17: 0.5 | E17: 0.5 | F17: 0.5 | G17: 0.62 | I17: 0.32 | J17: 0.15 | K17: 0.23 | L17: 0.37
A18: GOA | B18: GOA | C18: 0.5 | D18: 0.5 | E18: 0.5 | F18: 0.5 | G18: 0.6 | I18: 0.39 | J18: 0.39 | K18: 0.39 | L18: 0.39
A19: GUJARAT - 1 A | B19: GUJARAT - AHEMDABAD | C19: 0.5 | D19: 0.5 | E19: 0.5 | F19: 0.5 | G19: 0.6 | I19: 0.389 | J19: 0.34407271 | K19: 0.3882094 | L19: 0.389
A20: GUJARAT - 2 B | B20: GUJARAT - VADODARA | C20: 0.5 | D20: 0.5 | E20: 0.5 | F20: 0.5 | G20: 0.6 | I20: #N/A | J20: #N/A | K20: #N/A | L20: #N/A
A21: GUJARAT - 3 RA | B21: GUJARAT - REST | C21: 0.5 | D21: 0.5 | E21: 0.5 | F21: 0.5 | G21: 0.6 | I21: 0 | J21: 0 | K21: 0 | L21: 0
A22: GUJARAT - 4 R | B22: GUJARAT - REST | C22: 0 | D22: 0 | E22: 0 | F22: 0 | G22: 0.54 | I22: 0 | J22: 0 | K22: 0 | L22: 0
A23: GUJARAT - 4 S | B23: GUJARAT - SURAT | C23: 0.5 | D23: 0.5 | E23: 0.5 | F23: 0.5 | G23: 0.6 | I23: #N/A | J23: #N/A | K23: #N/A | L23: #N/A
A24: HARYANA - 1 R | B24: HARYANA - REST | C24: 0 | D24: 0 | E24: 0 | F24: 0 | G24: 0 | I24: 0 | J24: 0 | K24: 0 | L24: 0
A25: HIMACHAL PRADESH - 1 KMSO | B25: HIMACHAL PRADESH - BILASPUR, MANDI, SOLAN, SHIMLA & MANALI | C25: 0.46 | D25: 0.46 | E25: 0.46 | F25: 0.46 | G25: 0.6 | I25: 0.37165656 | J25: 0.26287349 | K25: 0.33697228 | L25: 0.389
A26: HIMACHAL PRADESH - 2 R | B26: HIMACHAL PRADESH - REST | C26: 0.46 | D26: 0.46 | E26: 0.46 | F26: 0.46 | G26: 0.6 | I26: 0.37295694 | J26: 0.25020398 | K26: 0.33898617 | L26: 0.389
A27: JAMMU & KASHMIR - 1 J | B27: JAMMU & KASHMIR - JAMMU | C27: 0.48 | D27: 0.24 | E27: 0.28 | F27: 0.48 | G27: 0.5 | I27: 0.22311137 | J27: 0.038676616 | K27: 0.14169178 | L27: 0.32641665
A28: JAMMU & KASHMIR - 2 R | B28: JAMMU & KASHMIR - REST | C28: 0.48 | D28: 0.48 | E28: 0.48 | F28: 0.48 | G28: 0.5 | I28: 0.4 | J28: 0.15924993 | K28: 0.2417384 | L28: 0.4
A29: JHARKHAND | B29: JHARKHAND | C29: 0.5 | D29: 0.55 | E29: 0.5 | F29: 0.55 | G29: 0.55 | I29: 0.45 | J29: 0.45 | K29: 0.45 | L29: 0.45
A30: KARNATAKA - 1 B | B30: KARNATAKA - BANGALORE | C30: 0.45 | D30: 0.27 | E30: 0.27 | F30: 0.39 | G30: 0.6 | I30: 0.45 | J30: 0.1201931 | K30: 0.12970802 | L30: 0.39
A31: KARNATAKA - 2 BD | B31: KARNATAKA - REST | C31: 0 | D31: 0 | E31: 0 | F31: 0 | G31: 0.52 | I31: 0 | J31: 0 | K31: 0 | L31: 0
A32: KARNATAKA - 3 MM | B32: KARNATAKA - BANGALORE SURROUNDING | C32: 0 | D32: 0 | E32: 0 | F32: 0 | G32: 0.34 | I32: #N/A | J32: #N/A | K32: #N/A | L32: #N/A
A33: KARNATAKA - 4 R | B33: KARNATAKA - REST | C33: 0 | D33: 0 | E33: 0 | F33: 0 | G33: 0 | I33: 0 | J33: 0 | K33: 0 | L33: 0
A34: KERALA - 1 CE | B34: KERALA - ERNAKULAM(COCHIN) | C34: 0 | D34: 0 | E34: 0 | F34: 0 | G34: 0 | I34: 0 | J34: 0 | K34: 0 | L34: 0
A35: KERALA - 2 N | B35: KERALA - NORTH | C35: 0 | D35: 0 | E35: 0 | F35: 0 | G35: 0 | I35: #N/A | J35: #N/A | K35: #N/A | L35: #N/A
A36: KERALA - 3 T | B36: KERALA - SOUTH | C36: 0 | D36: 0 | E36: 0 | F36: 0 | G36: 0 | I36: #N/A | J36: #N/A | K36: #N/A | L36: #N/A
A37: KERALA - 4 R | B37: KERALA - SOUTH | C37: 0 | D37: 0 | E37: 0 | F37: 0 | G37: 0 | I37: #N/A | J37: #N/A | K37: #N/A | L37: #N/A
A38: MADHYA PRADESH - 1 BI | B38: MADHYA PRADESH - BHOPAL & INDORE | C38: 0.235 | D38: 0.235 | E38: 0.235 | F38: 0.235 | G38: 0.5 | I38: 0 | J38: 0 | K38: 0 | L38: 0
A39: MADHYA PRADESH - 2 GJ | B39: MADHYA PRADESH - GWALIOR & JABALPUR | C39: 0 | D39: 0 | E39: 0 | F39: 0 | G39: 0 | I39: #N/A | J39: #N/A | K39: #N/A | L39: #N/A
A40: MADHYA PRADESH - 3 R | B40: MADHYA PRADESH - REST | C40: 0 | D40: 0 | E40: 0 | F40: 0 | G40: 0 | I40: 0 | J40: 0 | K40: 0 | L40: 0
A41: MAHARASHTRA - 1 M | B41: MAHARASHTRA - MUMBAI | C41: 0.5 | D41: 0.5 | E41: 0.5 | F41: 0.5 | G41: 0.6 | I41: #N/A | J41: #N/A | K41: #N/A | L41: #N/A
...

Sheet TW SATP_R
A1: March 2025 PAYOUT_TW SATP
A2: Segement | B2: Bikes | F2: Scooter
A3: Geo Location - New | B3: < 75 CC | C3: >75-150 CC | D3: > 150-350 CC | E3: > 350 CC | F3: < 75 CC | G3: >75-150 CC
A4: ANDHRA PRADESH - KRISHNA(VIJAYWADA) | B4: 0 | C4: 0 | D4: 0 | E4: 0 | F4: 0 | G4: 0
A5: ANDHRA PRADESH - REST | B5: 0 | C5: 0 | D5: 0 | E5: 0 | F5: 0 | G5: 0
A6: ANDHRA PRADESH - VISAKHAPATNAM | B6: 0 | C6: 0 | D6: 0 | E6: 0 | F6: 0 | G6: 0
A7: ARUNACHAL PRADESH | B7: 0 | C7: 0 | D7: 0 | E7: 0 | F7: 0 | G7: 0
A8: ASSAM - KAMRUP (GUWAHATI) | B8: 0 | C8: 0 | D8: 0 | E8: 0 | F8: 0 | G8: 0
A9: ASSAM - LOWER | B9: 0 | C9: 0 | D9: 0 | E9: 0 | F9: 0 | G9: 0
A10: ASSAM - UPPER | B10: 0 | C10: 0 | D10: 0 | E10: 0 | F10: 0 | G10: 0
A11: BIHAR | B11: 0 | C11: 0 | D11: 0 | E11: 0 | F11: 0 | G11: 0
A12: CHANDIGARH(TRICITY) | B12: 0 | C12: 0 | D12: 0 | E12: 0 | F12: 0 | G12: 0
A13: CHATTISGARH - RAIPUR | B13: 0 | C13: 0 | D13: 0 | E13: 0 | F13: 0 | G13: 0
A14: CHATTISGARH - REST | B14: 0 | C14: 0 | D14: 0 | E14: 0 | F14: 0 | G14: 0
A15: DELHI - NCR | B15: 0 | C15: 0 | D15: 0 | E15: 0 | F15: 0 | G15: 0
... A65: WEST BENGAL - REST | B65: 0 | C65: 0 | D65: 0 | E65: 0 | F65: 0 | G65: 0

Sheet TW SATP
A1: FEB 2025 PAYOUT_TW SATP
A2: Segement | B2: Bikes | F2: Scooter
A3: Geo Location - New | B3: < 75 CC | C3: >75-150 CC | D3: > 150-350 CC | E3: > 350 CC | F3: < 75 CC | G3: >75-150 CC
A4: ANDHRA PRADESH - KRISHNA(VIJAYWADA) | B4: 0 | C4: 0 | D4: 0 | E4: 0 | F4: 0 | G4: 0 | H4: =VLOOKUP(A4,'TW SATP_R'!$A$4:$A$127,1,0) -> ANDHRA PRADESH - KRISHNA(VIJAYWADA)
A5: ANDHRA PRADESH - REST | B5: 0 | C5: 0 | D5: 0 | E5: 0 | F5: 0 | G5: 0 | H5: =VLOOKUP(A5,'TW SATP_R'!$A$4:$A$127,1,0) -> ANDHRA PRADESH - REST
A6: ANDHRA PRADESH - VISAKHAPATNAM | B6: 0 | C6: 0 | D6: 0 | E6: 0 | F6: 0 | G6: 0 | H6: =VLOOKUP(A6,'TW SATP_R'!$A$4:$A$127,1,0) -> ANDHRA PRADESH - VISAKHAPATNAM
A7: KARNATAKA - BANGALORE | B7: 0.26 | C7: 0.4 | D7: 0.31 | E7: 0.24 | F7: 0.46 | G7: 0.52 | H7: =VLOOKUP(A7,'TW SATP_R'!$A$4:$A$127,1,0) -> KARNATAKA - BANGALORE
A8: TELANGANA - HYDERABAD & SURRONDING | B8: 0 | C8: 0.42 | D8: 0.25 | E8: 0.25 | F8: 0.47 | G8: 0.53 | H8: =VLOOKUP(A8,'TW SATP_R'!$A$4:$A$127,1,0) -> TELANGANA - HYDERABAD & SURRONDING
A9: TELANGANA - REST | B9: 0 | C9: 0.42 | D9: 0.25 | E9: 0.25 | F9: 0.47 | G9: 0.53 | H9: =VLOOKUP(A9,'TW SATP_R'!$A$4:$A$127,1,0) -> TELANGANA - REST
A10: GOA | B10: 0 | C10: 0 | D10: 0 | E10: 0 | F10: 0 | G10: 0 | H10: =VLOOKUP(A10,'TW SATP_R'!$A$4:$A$127,1,0) -> GOA
A11: MADHYA PRADESH - BHOPAL & INDORE | B11: 0 | C11: 0 | D11: 0 | E11: 0 | F11: 0 | G11: 0 | H11: =VLOOKUP(A11,'TW SATP_R'!$A$4:$A$127,1,0) -> MADHYA PRADESH - BHOPAL & INDORE
A12: MADHYA PRADESH - GWALIOR & JABALPUR | B12: 0 | C12: 0 | D12: 0 | E12: 0 | F12: 0 | G12: 0 | H12: =VLOOKUP(A12,'TW SATP_R'!$A$4:$A$127,1,0) -> MADHYA PRADESH - GWALIOR & JABALPUR
A13: MADHYA PRADESH - REST | B13: 0 | C13: 0 | D13: 0 | E13: 0 | F13: 0 | G13: 0 | H13: =VLOOKUP(A13,'TW SATP_R'!$A$4:$A$127,1,0) -> MADHYA PRADESH - REST
A14: MAHARASHTRA - MUMBAI | B14: 0.465 | C14: 0.45 | D14: 0.41 | E14: 0.34 | F14: 0.54 | G14: 0.56 | H14: =VLOOKUP(A14,'TW SATP_R'!$A$4:$A$127,1,0) -> MAHARASHTRA - MUMBAI
A15: MAHARASHTRA - NAGPUR | B15: 0 | C15: 0 | D15: 0 | E15: 0 | F15: 0 | G15: 0 | H15: =VLOOKUP(A15,'TW SATP_R'!$A$4:$A$127,1,0) -> MAHARASHTRA - NAGPUR
... A26: CHANDIGARH(TRICITY) | B26: 0 | C26: 0 | D26: 0 | E26: 0 | F26: 0 | G26: 0 | H26: =VLOOKUP(A26,'TW SATP_R'!$A$4:$A$127,1,0) -> CHANDIGARH(TRICITY)

Sheet CL & Health
A1: March
A2: Product | B2: Type | C2: Payout %
A3: Retail Health | B3: New | C3: 0.25
B4: Renewal | C4: 0.125
A5: Group Health | C5: 0.075
A6: Commercial Lines* | C6: 0.3
A8: *CL - Excluding Terrorism
